[2018-04-18 22:17:10 +0000] [9933] [INFO] Starting gunicorn 19.7.1
[2018-04-18 22:17:10 +0000] [9933] [INFO] Listening at: http://0.0.0.0:7279 (9933)
[2018-04-18 22:17:10 +0000] [9933] [INFO] Using worker: sync
[2018-04-18 22:17:10 +0000] [9937] [INFO] Booting worker with pid: 9937
[2018-04-18 22:17:10 +0000] [9937] [ERROR] Exception in worker process
Traceback (most recent call last):
  File "/root/venv/local/lib/python2.7/site-packages/gunicorn/arbiter.py", line 578, in spawn_worker
    worker.init_process()
  File "/root/venv/local/lib/python2.7/site-packages/gunicorn/workers/base.py", line 126, in init_process
    self.load_wsgi()
  File "/root/venv/local/lib/python2.7/site-packages/gunicorn/workers/base.py", line 135, in load_wsgi
    self.wsgi = self.app.wsgi()
  File "/root/venv/local/lib/python2.7/site-packages/gunicorn/app/base.py", line 67, in wsgi
    self.callable = self.load()
  File "/root/venv/local/lib/python2.7/site-packages/gunicorn/app/wsgiapp.py", line 65, in load
    return self.load_wsgiapp()
  File "/root/venv/local/lib/python2.7/site-packages/gunicorn/app/wsgiapp.py", line 52, in load_wsgiapp
    return util.import_app(self.app_uri)
  File "/root/venv/local/lib/python2.7/site-packages/gunicorn/util.py", line 352, in import_app
    __import__(module)
ImportError: No module named Example.wsgi
[2018-04-18 22:17:10 +0000] [9937] [INFO] Worker exiting (pid: 9937)
[2018-04-18 22:17:10 +0000] [9933] [INFO] Shutting down: Master
[2018-04-18 22:17:10 +0000] [9933] [INFO] Reason: Worker failed to boot.
[2018-04-18 22:17:11 +0000] [9938] [INFO] Starting gunicorn 19.7.1
[2018-04-18 22:17:11 +0000] [9938] [INFO] Listening at: http://0.0.0.0:7279 (9938)
[2018-04-18 22:17:11 +0000] [9938] [INFO] Using worker: sync
[2018-04-18 22:17:11 +0000] [9942] [INFO] Booting worker with pid: 9942
[2018-04-18 22:17:11 +0000] [9942] [ERROR] Exception in worker process
Traceback (most recent call last):
  File "/root/venv/local/lib/python2.7/site-packages/gunicorn/arbiter.py", line 578, in spawn_worker
    worker.init_process()
  File "/root/venv/local/lib/python2.7/site-packages/gunicorn/workers/base.py", line 126, in init_process
    self.load_wsgi()
  File "/root/venv/local/lib/python2.7/site-packages/gunicorn/workers/base.py", line 135, in load_wsgi
    self.wsgi = self.app.wsgi()
  File "/root/venv/local/lib/python2.7/site-packages/gunicorn/app/base.py", line 67, in wsgi
    self.callable = self.load()
  File "/root/venv/local/lib/python2.7/site-packages/gunicorn/app/wsgiapp.py", line 65, in load
    return self.load_wsgiapp()
  File "/root/venv/local/lib/python2.7/site-packages/gunicorn/app/wsgiapp.py", line 52, in load_wsgiapp
    return util.import_app(self.app_uri)
  File "/root/venv/local/lib/python2.7/site-packages/gunicorn/util.py", line 352, in import_app
    __import__(module)
ImportError: No module named Example.wsgi
[2018-04-18 22:17:11 +0000] [9942] [INFO] Worker exiting (pid: 9942)
[2018-04-18 22:17:11 +0000] [9938] [INFO] Shutting down: Master
[2018-04-18 22:17:11 +0000] [9938] [INFO] Reason: Worker failed to boot.
[2018-04-18 22:17:13 +0000] [9943] [INFO] Starting gunicorn 19.7.1
[2018-04-18 22:17:13 +0000] [9943] [INFO] Listening at: http://0.0.0.0:7279 (9943)
[2018-04-18 22:17:13 +0000] [9943] [INFO] Using worker: sync
[2018-04-18 22:17:13 +0000] [9947] [INFO] Booting worker with pid: 9947
[2018-04-18 22:17:13 +0000] [9947] [ERROR] Exception in worker process
Traceback (most recent call last):
  File "/root/venv/local/lib/python2.7/site-packages/gunicorn/arbiter.py", line 578, in spawn_worker
    worker.init_process()
  File "/root/venv/local/lib/python2.7/site-packages/gunicorn/workers/base.py", line 126, in init_process
    self.load_wsgi()
  File "/root/venv/local/lib/python2.7/site-packages/gunicorn/workers/base.py", line 135, in load_wsgi
    self.wsgi = self.app.wsgi()
  File "/root/venv/local/lib/python2.7/site-packages/gunicorn/app/base.py", line 67, in wsgi
    self.callable = self.load()
  File "/root/venv/local/lib/python2.7/site-packages/gunicorn/app/wsgiapp.py", line 65, in load
    return self.load_wsgiapp()
  File "/root/venv/local/lib/python2.7/site-packages/gunicorn/app/wsgiapp.py", line 52, in load_wsgiapp
    return util.import_app(self.app_uri)
  File "/root/venv/local/lib/python2.7/site-packages/gunicorn/util.py", line 352, in import_app
    __import__(module)
ImportError: No module named Example.wsgi
[2018-04-18 22:17:13 +0000] [9947] [INFO] Worker exiting (pid: 9947)
[2018-04-18 22:17:13 +0000] [9943] [INFO] Shutting down: Master
[2018-04-18 22:17:13 +0000] [9943] [INFO] Reason: Worker failed to boot.
[2018-04-18 22:17:16 +0000] [9948] [INFO] Starting gunicorn 19.7.1
[2018-04-18 22:17:16 +0000] [9948] [INFO] Listening at: http://0.0.0.0:7279 (9948)
[2018-04-18 22:17:16 +0000] [9948] [INFO] Using worker: sync
[2018-04-18 22:17:16 +0000] [9952] [INFO] Booting worker with pid: 9952
[2018-04-18 22:17:16 +0000] [9952] [ERROR] Exception in worker process
Traceback (most recent call last):
  File "/root/venv/local/lib/python2.7/site-packages/gunicorn/arbiter.py", line 578, in spawn_worker
    worker.init_process()
  File "/root/venv/local/lib/python2.7/site-packages/gunicorn/workers/base.py", line 126, in init_process
    self.load_wsgi()
  File "/root/venv/local/lib/python2.7/site-packages/gunicorn/workers/base.py", line 135, in load_wsgi
    self.wsgi = self.app.wsgi()
  File "/root/venv/local/lib/python2.7/site-packages/gunicorn/app/base.py", line 67, in wsgi
    self.callable = self.load()
  File "/root/venv/local/lib/python2.7/site-packages/gunicorn/app/wsgiapp.py", line 65, in load
    return self.load_wsgiapp()
  File "/root/venv/local/lib/python2.7/site-packages/gunicorn/app/wsgiapp.py", line 52, in load_wsgiapp
    return util.import_app(self.app_uri)
  File "/root/venv/local/lib/python2.7/site-packages/gunicorn/util.py", line 352, in import_app
    __import__(module)
ImportError: No module named Example.wsgi
[2018-04-18 22:17:16 +0000] [9952] [INFO] Worker exiting (pid: 9952)
[2018-04-18 22:17:16 +0000] [9948] [INFO] Shutting down: Master
[2018-04-18 22:17:16 +0000] [9948] [INFO] Reason: Worker failed to boot.
[2018-04-18 22:20:15 +0000] [9999] [INFO] Starting gunicorn 19.7.1
[2018-04-18 22:20:15 +0000] [9999] [INFO] Listening at: http://0.0.0.0:7279 (9999)
[2018-04-18 22:20:15 +0000] [9999] [INFO] Using worker: sync
[2018-04-18 22:20:15 +0000] [10003] [INFO] Booting worker with pid: 10003
[2018-04-18 22:20:15 +0000] [10003] [ERROR] Exception in worker process
Traceback (most recent call last):
  File "/root/venv/local/lib/python2.7/site-packages/gunicorn/arbiter.py", line 578, in spawn_worker
    worker.init_process()
  File "/root/venv/local/lib/python2.7/site-packages/gunicorn/workers/base.py", line 126, in init_process
    self.load_wsgi()
  File "/root/venv/local/lib/python2.7/site-packages/gunicorn/workers/base.py", line 135, in load_wsgi
    self.wsgi = self.app.wsgi()
  File "/root/venv/local/lib/python2.7/site-packages/gunicorn/app/base.py", line 67, in wsgi
    self.callable = self.load()
  File "/root/venv/local/lib/python2.7/site-packages/gunicorn/app/wsgiapp.py", line 65, in load
    return self.load_wsgiapp()
  File "/root/venv/local/lib/python2.7/site-packages/gunicorn/app/wsgiapp.py", line 52, in load_wsgiapp
    return util.import_app(self.app_uri)
  File "/root/venv/local/lib/python2.7/site-packages/gunicorn/util.py", line 352, in import_app
    __import__(module)
ImportError: No module named Example.wsgi
[2018-04-18 22:20:15 +0000] [10003] [INFO] Worker exiting (pid: 10003)
[2018-04-18 22:20:15 +0000] [9999] [INFO] Shutting down: Master
[2018-04-18 22:20:15 +0000] [9999] [INFO] Reason: Worker failed to boot.
[2018-04-18 22:20:17 +0000] [10004] [INFO] Starting gunicorn 19.7.1
[2018-04-18 22:20:17 +0000] [10004] [INFO] Listening at: http://0.0.0.0:7279 (10004)
[2018-04-18 22:20:17 +0000] [10004] [INFO] Using worker: sync
[2018-04-18 22:20:17 +0000] [10008] [INFO] Booting worker with pid: 10008
[2018-04-18 22:20:17 +0000] [10008] [ERROR] Exception in worker process
Traceback (most recent call last):
  File "/root/venv/local/lib/python2.7/site-packages/gunicorn/arbiter.py", line 578, in spawn_worker
    worker.init_process()
  File "/root/venv/local/lib/python2.7/site-packages/gunicorn/workers/base.py", line 126, in init_process
    self.load_wsgi()
  File "/root/venv/local/lib/python2.7/site-packages/gunicorn/workers/base.py", line 135, in load_wsgi
    self.wsgi = self.app.wsgi()
  File "/root/venv/local/lib/python2.7/site-packages/gunicorn/app/base.py", line 67, in wsgi
    self.callable = self.load()
  File "/root/venv/local/lib/python2.7/site-packages/gunicorn/app/wsgiapp.py", line 65, in load
    return self.load_wsgiapp()
  File "/root/venv/local/lib/python2.7/site-packages/gunicorn/app/wsgiapp.py", line 52, in load_wsgiapp
    return util.import_app(self.app_uri)
  File "/root/venv/local/lib/python2.7/site-packages/gunicorn/util.py", line 352, in import_app
    __import__(module)
ImportError: No module named Example.wsgi
[2018-04-18 22:20:17 +0000] [10008] [INFO] Worker exiting (pid: 10008)
[2018-04-18 22:20:17 +0000] [10004] [INFO] Shutting down: Master
[2018-04-18 22:20:17 +0000] [10004] [INFO] Reason: Worker failed to boot.
[2018-04-18 22:20:19 +0000] [10009] [INFO] Starting gunicorn 19.7.1
[2018-04-18 22:20:19 +0000] [10009] [INFO] Listening at: http://0.0.0.0:7279 (10009)
[2018-04-18 22:20:19 +0000] [10009] [INFO] Using worker: sync
[2018-04-18 22:20:19 +0000] [10013] [INFO] Booting worker with pid: 10013
[2018-04-18 22:20:19 +0000] [10013] [ERROR] Exception in worker process
Traceback (most recent call last):
  File "/root/venv/local/lib/python2.7/site-packages/gunicorn/arbiter.py", line 578, in spawn_worker
    worker.init_process()
  File "/root/venv/local/lib/python2.7/site-packages/gunicorn/workers/base.py", line 126, in init_process
    self.load_wsgi()
  File "/root/venv/local/lib/python2.7/site-packages/gunicorn/workers/base.py", line 135, in load_wsgi
    self.wsgi = self.app.wsgi()
  File "/root/venv/local/lib/python2.7/site-packages/gunicorn/app/base.py", line 67, in wsgi
    self.callable = self.load()
  File "/root/venv/local/lib/python2.7/site-packages/gunicorn/app/wsgiapp.py", line 65, in load
    return self.load_wsgiapp()
  File "/root/venv/local/lib/python2.7/site-packages/gunicorn/app/wsgiapp.py", line 52, in load_wsgiapp
    return util.import_app(self.app_uri)
  File "/root/venv/local/lib/python2.7/site-packages/gunicorn/util.py", line 352, in import_app
    __import__(module)
ImportError: No module named Example.wsgi
[2018-04-18 22:20:19 +0000] [10013] [INFO] Worker exiting (pid: 10013)
[2018-04-18 22:20:19 +0000] [10009] [INFO] Shutting down: Master
[2018-04-18 22:20:19 +0000] [10009] [INFO] Reason: Worker failed to boot.
[2018-04-18 22:20:22 +0000] [10014] [INFO] Starting gunicorn 19.7.1
[2018-04-18 22:20:22 +0000] [10014] [INFO] Listening at: http://0.0.0.0:7279 (10014)
[2018-04-18 22:20:22 +0000] [10014] [INFO] Using worker: sync
[2018-04-18 22:20:22 +0000] [10020] [INFO] Booting worker with pid: 10020
[2018-04-18 22:20:22 +0000] [10020] [ERROR] Exception in worker process
Traceback (most recent call last):
  File "/root/venv/local/lib/python2.7/site-packages/gunicorn/arbiter.py", line 578, in spawn_worker
    worker.init_process()
  File "/root/venv/local/lib/python2.7/site-packages/gunicorn/workers/base.py", line 126, in init_process
    self.load_wsgi()
  File "/root/venv/local/lib/python2.7/site-packages/gunicorn/workers/base.py", line 135, in load_wsgi
    self.wsgi = self.app.wsgi()
  File "/root/venv/local/lib/python2.7/site-packages/gunicorn/app/base.py", line 67, in wsgi
    self.callable = self.load()
  File "/root/venv/local/lib/python2.7/site-packages/gunicorn/app/wsgiapp.py", line 65, in load
    return self.load_wsgiapp()
  File "/root/venv/local/lib/python2.7/site-packages/gunicorn/app/wsgiapp.py", line 52, in load_wsgiapp
    return util.import_app(self.app_uri)
  File "/root/venv/local/lib/python2.7/site-packages/gunicorn/util.py", line 352, in import_app
    __import__(module)
ImportError: No module named Example.wsgi
[2018-04-18 22:20:22 +0000] [10020] [INFO] Worker exiting (pid: 10020)
[2018-04-18 22:20:22 +0000] [10014] [INFO] Shutting down: Master
[2018-04-18 22:20:22 +0000] [10014] [INFO] Reason: Worker failed to boot.
[2018-04-18 22:25:38 +0000] [10088] [INFO] Starting gunicorn 19.7.1
[2018-04-18 22:25:38 +0000] [10088] [INFO] Listening at: http://0.0.0.0:7279 (10088)
[2018-04-18 22:25:38 +0000] [10088] [INFO] Using worker: sync
[2018-04-18 22:25:38 +0000] [10092] [INFO] Booting worker with pid: 10092
[2018-04-18 22:25:38 +0000] [10092] [ERROR] Exception in worker process
Traceback (most recent call last):
  File "/root/venv/local/lib/python2.7/site-packages/gunicorn/arbiter.py", line 578, in spawn_worker
    worker.init_process()
  File "/root/venv/local/lib/python2.7/site-packages/gunicorn/workers/base.py", line 126, in init_process
    self.load_wsgi()
  File "/root/venv/local/lib/python2.7/site-packages/gunicorn/workers/base.py", line 135, in load_wsgi
    self.wsgi = self.app.wsgi()
  File "/root/venv/local/lib/python2.7/site-packages/gunicorn/app/base.py", line 67, in wsgi
    self.callable = self.load()
  File "/root/venv/local/lib/python2.7/site-packages/gunicorn/app/wsgiapp.py", line 65, in load
    return self.load_wsgiapp()
  File "/root/venv/local/lib/python2.7/site-packages/gunicorn/app/wsgiapp.py", line 52, in load_wsgiapp
    return util.import_app(self.app_uri)
  File "/root/venv/local/lib/python2.7/site-packages/gunicorn/util.py", line 352, in import_app
    __import__(module)
ImportError: No module named Example.wsgi
[2018-04-18 22:25:38 +0000] [10092] [INFO] Worker exiting (pid: 10092)
[2018-04-18 22:25:38 +0000] [10088] [INFO] Shutting down: Master
[2018-04-18 22:25:38 +0000] [10088] [INFO] Reason: Worker failed to boot.
[2018-04-18 22:25:40 +0000] [10093] [INFO] Starting gunicorn 19.7.1
[2018-04-18 22:25:40 +0000] [10093] [INFO] Listening at: http://0.0.0.0:7279 (10093)
[2018-04-18 22:25:40 +0000] [10093] [INFO] Using worker: sync
[2018-04-18 22:25:40 +0000] [10097] [INFO] Booting worker with pid: 10097
[2018-04-18 22:25:40 +0000] [10097] [ERROR] Exception in worker process
Traceback (most recent call last):
  File "/root/venv/local/lib/python2.7/site-packages/gunicorn/arbiter.py", line 578, in spawn_worker
    worker.init_process()
  File "/root/venv/local/lib/python2.7/site-packages/gunicorn/workers/base.py", line 126, in init_process
    self.load_wsgi()
  File "/root/venv/local/lib/python2.7/site-packages/gunicorn/workers/base.py", line 135, in load_wsgi
    self.wsgi = self.app.wsgi()
  File "/root/venv/local/lib/python2.7/site-packages/gunicorn/app/base.py", line 67, in wsgi
    self.callable = self.load()
  File "/root/venv/local/lib/python2.7/site-packages/gunicorn/app/wsgiapp.py", line 65, in load
    return self.load_wsgiapp()
  File "/root/venv/local/lib/python2.7/site-packages/gunicorn/app/wsgiapp.py", line 52, in load_wsgiapp
    return util.import_app(self.app_uri)
  File "/root/venv/local/lib/python2.7/site-packages/gunicorn/util.py", line 352, in import_app
    __import__(module)
ImportError: No module named Example.wsgi
[2018-04-18 22:25:40 +0000] [10097] [INFO] Worker exiting (pid: 10097)
[2018-04-18 22:25:40 +0000] [10093] [INFO] Shutting down: Master
[2018-04-18 22:25:40 +0000] [10093] [INFO] Reason: Worker failed to boot.
[2018-04-18 22:25:42 +0000] [10098] [INFO] Starting gunicorn 19.7.1
[2018-04-18 22:25:42 +0000] [10098] [INFO] Listening at: http://0.0.0.0:7279 (10098)
[2018-04-18 22:25:42 +0000] [10098] [INFO] Using worker: sync
[2018-04-18 22:25:42 +0000] [10102] [INFO] Booting worker with pid: 10102
[2018-04-18 22:25:42 +0000] [10102] [ERROR] Exception in worker process
Traceback (most recent call last):
  File "/root/venv/local/lib/python2.7/site-packages/gunicorn/arbiter.py", line 578, in spawn_worker
    worker.init_process()
  File "/root/venv/local/lib/python2.7/site-packages/gunicorn/workers/base.py", line 126, in init_process
    self.load_wsgi()
  File "/root/venv/local/lib/python2.7/site-packages/gunicorn/workers/base.py", line 135, in load_wsgi
    self.wsgi = self.app.wsgi()
  File "/root/venv/local/lib/python2.7/site-packages/gunicorn/app/base.py", line 67, in wsgi
    self.callable = self.load()
  File "/root/venv/local/lib/python2.7/site-packages/gunicorn/app/wsgiapp.py", line 65, in load
    return self.load_wsgiapp()
  File "/root/venv/local/lib/python2.7/site-packages/gunicorn/app/wsgiapp.py", line 52, in load_wsgiapp
    return util.import_app(self.app_uri)
  File "/root/venv/local/lib/python2.7/site-packages/gunicorn/util.py", line 352, in import_app
    __import__(module)
ImportError: No module named Example.wsgi
[2018-04-18 22:25:42 +0000] [10102] [INFO] Worker exiting (pid: 10102)
[2018-04-18 22:25:42 +0000] [10098] [INFO] Shutting down: Master
[2018-04-18 22:25:42 +0000] [10098] [INFO] Reason: Worker failed to boot.
[2018-04-18 22:25:45 +0000] [10103] [INFO] Starting gunicorn 19.7.1
[2018-04-18 22:25:45 +0000] [10103] [INFO] Listening at: http://0.0.0.0:7279 (10103)
[2018-04-18 22:25:45 +0000] [10103] [INFO] Using worker: sync
[2018-04-18 22:25:45 +0000] [10107] [INFO] Booting worker with pid: 10107
[2018-04-18 22:25:45 +0000] [10107] [ERROR] Exception in worker process
Traceback (most recent call last):
  File "/root/venv/local/lib/python2.7/site-packages/gunicorn/arbiter.py", line 578, in spawn_worker
    worker.init_process()
  File "/root/venv/local/lib/python2.7/site-packages/gunicorn/workers/base.py", line 126, in init_process
    self.load_wsgi()
  File "/root/venv/local/lib/python2.7/site-packages/gunicorn/workers/base.py", line 135, in load_wsgi
    self.wsgi = self.app.wsgi()
  File "/root/venv/local/lib/python2.7/site-packages/gunicorn/app/base.py", line 67, in wsgi
    self.callable = self.load()
  File "/root/venv/local/lib/python2.7/site-packages/gunicorn/app/wsgiapp.py", line 65, in load
    return self.load_wsgiapp()
  File "/root/venv/local/lib/python2.7/site-packages/gunicorn/app/wsgiapp.py", line 52, in load_wsgiapp
    return util.import_app(self.app_uri)
  File "/root/venv/local/lib/python2.7/site-packages/gunicorn/util.py", line 352, in import_app
    __import__(module)
ImportError: No module named Example.wsgi
[2018-04-18 22:25:45 +0000] [10107] [INFO] Worker exiting (pid: 10107)
[2018-04-18 22:25:45 +0000] [10103] [INFO] Shutting down: Master
[2018-04-18 22:25:45 +0000] [10103] [INFO] Reason: Worker failed to boot.
[2018-04-18 22:30:41 +0000] [10187] [INFO] Starting gunicorn 19.7.1
[2018-04-18 22:30:41 +0000] [10187] [INFO] Listening at: http://0.0.0.0:7279 (10187)
[2018-04-18 22:30:41 +0000] [10187] [INFO] Using worker: sync
[2018-04-18 22:30:41 +0000] [10191] [INFO] Booting worker with pid: 10191
[2018-04-18 22:30:41 +0000] [10191] [ERROR] Exception in worker process
Traceback (most recent call last):
  File "/root/venv/local/lib/python2.7/site-packages/gunicorn/arbiter.py", line 578, in spawn_worker
    worker.init_process()
  File "/root/venv/local/lib/python2.7/site-packages/gunicorn/workers/base.py", line 126, in init_process
    self.load_wsgi()
  File "/root/venv/local/lib/python2.7/site-packages/gunicorn/workers/base.py", line 135, in load_wsgi
    self.wsgi = self.app.wsgi()
  File "/root/venv/local/lib/python2.7/site-packages/gunicorn/app/base.py", line 67, in wsgi
    self.callable = self.load()
  File "/root/venv/local/lib/python2.7/site-packages/gunicorn/app/wsgiapp.py", line 65, in load
    return self.load_wsgiapp()
  File "/root/venv/local/lib/python2.7/site-packages/gunicorn/app/wsgiapp.py", line 52, in load_wsgiapp
    return util.import_app(self.app_uri)
  File "/root/venv/local/lib/python2.7/site-packages/gunicorn/util.py", line 352, in import_app
    __import__(module)
ImportError: No module named Example.wsgi
[2018-04-18 22:30:41 +0000] [10191] [INFO] Worker exiting (pid: 10191)
[2018-04-18 22:30:41 +0000] [10187] [INFO] Shutting down: Master
[2018-04-18 22:30:41 +0000] [10187] [INFO] Reason: Worker failed to boot.
[2018-04-18 22:30:42 +0000] [10192] [INFO] Starting gunicorn 19.7.1
[2018-04-18 22:30:42 +0000] [10192] [INFO] Listening at: http://0.0.0.0:7279 (10192)
[2018-04-18 22:30:42 +0000] [10192] [INFO] Using worker: sync
[2018-04-18 22:30:42 +0000] [10196] [INFO] Booting worker with pid: 10196
[2018-04-18 22:30:42 +0000] [10196] [ERROR] Exception in worker process
Traceback (most recent call last):
  File "/root/venv/local/lib/python2.7/site-packages/gunicorn/arbiter.py", line 578, in spawn_worker
    worker.init_process()
  File "/root/venv/local/lib/python2.7/site-packages/gunicorn/workers/base.py", line 126, in init_process
    self.load_wsgi()
  File "/root/venv/local/lib/python2.7/site-packages/gunicorn/workers/base.py", line 135, in load_wsgi
    self.wsgi = self.app.wsgi()
  File "/root/venv/local/lib/python2.7/site-packages/gunicorn/app/base.py", line 67, in wsgi
    self.callable = self.load()
  File "/root/venv/local/lib/python2.7/site-packages/gunicorn/app/wsgiapp.py", line 65, in load
    return self.load_wsgiapp()
  File "/root/venv/local/lib/python2.7/site-packages/gunicorn/app/wsgiapp.py", line 52, in load_wsgiapp
    return util.import_app(self.app_uri)
  File "/root/venv/local/lib/python2.7/site-packages/gunicorn/util.py", line 352, in import_app
    __import__(module)
ImportError: No module named Example.wsgi
[2018-04-18 22:30:42 +0000] [10196] [INFO] Worker exiting (pid: 10196)
[2018-04-18 22:30:42 +0000] [10192] [INFO] Shutting down: Master
[2018-04-18 22:30:42 +0000] [10192] [INFO] Reason: Worker failed to boot.
[2018-04-18 22:30:45 +0000] [10197] [INFO] Starting gunicorn 19.7.1
[2018-04-18 22:30:45 +0000] [10197] [INFO] Listening at: http://0.0.0.0:7279 (10197)
[2018-04-18 22:30:45 +0000] [10197] [INFO] Using worker: sync
[2018-04-18 22:30:45 +0000] [10201] [INFO] Booting worker with pid: 10201
[2018-04-18 22:30:45 +0000] [10201] [ERROR] Exception in worker process
Traceback (most recent call last):
  File "/root/venv/local/lib/python2.7/site-packages/gunicorn/arbiter.py", line 578, in spawn_worker
    worker.init_process()
  File "/root/venv/local/lib/python2.7/site-packages/gunicorn/workers/base.py", line 126, in init_process
    self.load_wsgi()
  File "/root/venv/local/lib/python2.7/site-packages/gunicorn/workers/base.py", line 135, in load_wsgi
    self.wsgi = self.app.wsgi()
  File "/root/venv/local/lib/python2.7/site-packages/gunicorn/app/base.py", line 67, in wsgi
    self.callable = self.load()
  File "/root/venv/local/lib/python2.7/site-packages/gunicorn/app/wsgiapp.py", line 65, in load
    return self.load_wsgiapp()
  File "/root/venv/local/lib/python2.7/site-packages/gunicorn/app/wsgiapp.py", line 52, in load_wsgiapp
    return util.import_app(self.app_uri)
  File "/root/venv/local/lib/python2.7/site-packages/gunicorn/util.py", line 352, in import_app
    __import__(module)
ImportError: No module named Example.wsgi
[2018-04-18 22:30:45 +0000] [10201] [INFO] Worker exiting (pid: 10201)
[2018-04-18 22:30:45 +0000] [10197] [INFO] Shutting down: Master
[2018-04-18 22:30:45 +0000] [10197] [INFO] Reason: Worker failed to boot.
[2018-04-18 22:30:48 +0000] [10202] [INFO] Starting gunicorn 19.7.1
[2018-04-18 22:30:48 +0000] [10202] [INFO] Listening at: http://0.0.0.0:7279 (10202)
[2018-04-18 22:30:48 +0000] [10202] [INFO] Using worker: sync
[2018-04-18 22:30:48 +0000] [10206] [INFO] Booting worker with pid: 10206
[2018-04-18 22:30:48 +0000] [10206] [ERROR] Exception in worker process
Traceback (most recent call last):
  File "/root/venv/local/lib/python2.7/site-packages/gunicorn/arbiter.py", line 578, in spawn_worker
    worker.init_process()
  File "/root/venv/local/lib/python2.7/site-packages/gunicorn/workers/base.py", line 126, in init_process
    self.load_wsgi()
  File "/root/venv/local/lib/python2.7/site-packages/gunicorn/workers/base.py", line 135, in load_wsgi
    self.wsgi = self.app.wsgi()
  File "/root/venv/local/lib/python2.7/site-packages/gunicorn/app/base.py", line 67, in wsgi
    self.callable = self.load()
  File "/root/venv/local/lib/python2.7/site-packages/gunicorn/app/wsgiapp.py", line 65, in load
    return self.load_wsgiapp()
  File "/root/venv/local/lib/python2.7/site-packages/gunicorn/app/wsgiapp.py", line 52, in load_wsgiapp
    return util.import_app(self.app_uri)
  File "/root/venv/local/lib/python2.7/site-packages/gunicorn/util.py", line 352, in import_app
    __import__(module)
ImportError: No module named Example.wsgi
[2018-04-18 22:30:48 +0000] [10206] [INFO] Worker exiting (pid: 10206)
[2018-04-18 22:30:48 +0000] [10202] [INFO] Shutting down: Master
[2018-04-18 22:30:48 +0000] [10202] [INFO] Reason: Worker failed to boot.
[2018-04-18 22:41:14 +0000] [10358] [INFO] Starting gunicorn 19.7.1
[2018-04-18 22:41:14 +0000] [10358] [INFO] Listening at: http://0.0.0.0:7279 (10358)
[2018-04-18 22:41:14 +0000] [10358] [INFO] Using worker: sync
[2018-04-18 22:41:14 +0000] [10362] [INFO] Booting worker with pid: 10362
[2018-04-18 22:43:12 +0000] [10358] [INFO] Handling signal: term
[2018-04-18 22:43:12 +0000] [10362] [INFO] Worker exiting (pid: 10362)
[2018-04-18 22:43:12 +0000] [10358] [INFO] Shutting down: Master
[2018-04-18 22:46:12 +0000] [10512] [INFO] Starting gunicorn 19.7.1
[2018-04-18 22:46:12 +0000] [10512] [INFO] Listening at: http://0.0.0.0:7279 (10512)
[2018-04-18 22:46:12 +0000] [10512] [INFO] Using worker: sync
[2018-04-18 22:46:12 +0000] [10517] [INFO] Booting worker with pid: 10517
Not Found: /css/style.css
Not Found: /css/style.css
Not Found: /css/style.css
Not Found: /css/style.css
Not Found: /css/style.css
Not Found: /css/style.css
Not Found: /css/style.css
Not Found: /favicon.ico
Not Found: /muieblackcat
Not Found: /phpmyadmin/scripts/setup.php
Not Found: /myadmin/scripts/setup.php
Not Found: /MyAdmin/scripts/setup.php
Not Found: /css/style.css
Not Found: /xmlrpc.php
Not Found: /css/style.css
Internal Server Error: /api/update_entry/
Traceback (most recent call last):
  File "/root/venv/local/lib/python2.7/site-packages/django/core/handlers/exception.py", line 41, in inner
    response = get_response(request)
  File "/root/venv/local/lib/python2.7/site-packages/django/core/handlers/base.py", line 187, in _get_response
    response = self.process_exception_by_middleware(e, request)
  File "/root/venv/local/lib/python2.7/site-packages/django/core/handlers/base.py", line 185, in _get_response
    response = wrapped_callback(request, *callback_args, **callback_kwargs)
  File "/root/convocation-spjimr/pages/views.py", line 20, in update_entry
    stud = Student.objects.get(id=int(stud_id))
ValueError: invalid literal for int() with base 10: 'undefined'
Internal Server Error: /api/update_entry/
Traceback (most recent call last):
  File "/root/venv/local/lib/python2.7/site-packages/django/core/handlers/exception.py", line 41, in inner
    response = get_response(request)
  File "/root/venv/local/lib/python2.7/site-packages/django/core/handlers/base.py", line 187, in _get_response
    response = self.process_exception_by_middleware(e, request)
  File "/root/venv/local/lib/python2.7/site-packages/django/core/handlers/base.py", line 185, in _get_response
    response = wrapped_callback(request, *callback_args, **callback_kwargs)
  File "/root/convocation-spjimr/pages/views.py", line 20, in update_entry
    stud = Student.objects.get(id=int(stud_id))
ValueError: invalid literal for int() with base 10: 'undefined'
Not Found: /css/style.css
Not Found: /css/style.css
Not Found: /css/style.css
Internal Server Error: /api/update_entry/
Traceback (most recent call last):
  File "/root/venv/local/lib/python2.7/site-packages/django/core/handlers/exception.py", line 41, in inner
    response = get_response(request)
  File "/root/venv/local/lib/python2.7/site-packages/django/core/handlers/base.py", line 187, in _get_response
    response = self.process_exception_by_middleware(e, request)
  File "/root/venv/local/lib/python2.7/site-packages/django/core/handlers/base.py", line 185, in _get_response
    response = wrapped_callback(request, *callback_args, **callback_kwargs)
  File "/root/convocation-spjimr/pages/views.py", line 20, in update_entry
    stud = Student.objects.get(id=int(stud_id))
ValueError: invalid literal for int() with base 10: 'undefined'
Internal Server Error: /api/update_entry/
Traceback (most recent call last):
  File "/root/venv/local/lib/python2.7/site-packages/django/core/handlers/exception.py", line 41, in inner
    response = get_response(request)
  File "/root/venv/local/lib/python2.7/site-packages/django/core/handlers/base.py", line 187, in _get_response
    response = self.process_exception_by_middleware(e, request)
  File "/root/venv/local/lib/python2.7/site-packages/django/core/handlers/base.py", line 185, in _get_response
    response = wrapped_callback(request, *callback_args, **callback_kwargs)
  File "/root/convocation-spjimr/pages/views.py", line 20, in update_entry
    stud = Student.objects.get(id=int(stud_id))
ValueError: invalid literal for int() with base 10: 'undefined'
Not Found: /css/style.css
Not Found: /css/style.css
Internal Server Error: /api/update_entry/
Traceback (most recent call last):
  File "/root/venv/local/lib/python2.7/site-packages/django/core/handlers/exception.py", line 41, in inner
    response = get_response(request)
  File "/root/venv/local/lib/python2.7/site-packages/django/core/handlers/base.py", line 187, in _get_response
    response = self.process_exception_by_middleware(e, request)
  File "/root/venv/local/lib/python2.7/site-packages/django/core/handlers/base.py", line 185, in _get_response
    response = wrapped_callback(request, *callback_args, **callback_kwargs)
  File "/root/convocation-spjimr/pages/views.py", line 20, in update_entry
    stud = Student.objects.get(id=int(stud_id))
ValueError: invalid literal for int() with base 10: 'undefined'
Not Found: /favicon.ico
Not Found: /css/style.css
Not Found: /favicon.ico
Internal Server Error: /api/update_entry/
Traceback (most recent call last):
  File "/root/venv/local/lib/python2.7/site-packages/django/core/handlers/exception.py", line 41, in inner
    response = get_response(request)
  File "/root/venv/local/lib/python2.7/site-packages/django/core/handlers/base.py", line 187, in _get_response
    response = self.process_exception_by_middleware(e, request)
  File "/root/venv/local/lib/python2.7/site-packages/django/core/handlers/base.py", line 185, in _get_response
    response = wrapped_callback(request, *callback_args, **callback_kwargs)
  File "/root/convocation-spjimr/pages/views.py", line 20, in update_entry
    stud = Student.objects.get(id=int(stud_id))
ValueError: invalid literal for int() with base 10: 'undefined'
Not Found: /administrator/manifests/files/joomla.xml
Not Found: /favicon.ico
Not Found: /user/register
Not Found: /rss.php
Not Found: /wp-login.php
Not Found: /user/register
Not Found: /rss.php
Not Found: /wp-login.php
Not Found: /Img/login-down.png
Not Found: /user/register
Not Found: /rss.php
Not Found: /wp-login.php
Not Found: /css/style.css
Not Found: /user/register
Not Found: /rss.php
Not Found: /wls-wsat/CoordinatorPortType
Not Found: /user/register
Not Found: /wp-login.php
Not Found: /wp-login.php
Not Found: /user/register
Not Found: /rss.php
Not Found: /user/register
Not Found: /rss.php
Not Found: /wp-login.php
Not Found: /wp-login.php
Not Found: /Img/login-down.png
Not Found: /user/register
Not Found: /wp-login.php
Not Found: /user/register
Not Found: /rss.php
Not Found: /wp-login.php
Not Found: /user/register
Not Found: /rss.php
Not Found: /css/style.css
Not Found: /css/style.css
Not Found: /css/style.css
Not Found: /css/style.css
Not Found: /css/style.css
Not Found: /css/style.css
Not Found: /css/style.css
Not Found: /favicon.ico
Not Found: /favicon.ico
Forbidden (CSRF cookie not set.): /
Not Found: /rss.php
Not Found: /wp-login.php
Not Found: /css/style.css
Internal Server Error: /api/update_entry/
Traceback (most recent call last):
  File "/root/venv/local/lib/python2.7/site-packages/django/core/handlers/exception.py", line 41, in inner
    response = get_response(request)
  File "/root/venv/local/lib/python2.7/site-packages/django/core/handlers/base.py", line 187, in _get_response
    response = self.process_exception_by_middleware(e, request)
  File "/root/venv/local/lib/python2.7/site-packages/django/core/handlers/base.py", line 185, in _get_response
    response = wrapped_callback(request, *callback_args, **callback_kwargs)
  File "/root/convocation-spjimr/pages/views.py", line 20, in update_entry
    stud = Student.objects.get(id=int(stud_id))
ValueError: invalid literal for int() with base 10: 'undefined'
Internal Server Error: /api/update_entry/
Traceback (most recent call last):
  File "/root/venv/local/lib/python2.7/site-packages/django/core/handlers/exception.py", line 41, in inner
    response = get_response(request)
  File "/root/venv/local/lib/python2.7/site-packages/django/core/handlers/base.py", line 187, in _get_response
    response = self.process_exception_by_middleware(e, request)
  File "/root/venv/local/lib/python2.7/site-packages/django/core/handlers/base.py", line 185, in _get_response
    response = wrapped_callback(request, *callback_args, **callback_kwargs)
  File "/root/convocation-spjimr/pages/views.py", line 20, in update_entry
    stud = Student.objects.get(id=int(stud_id))
ValueError: invalid literal for int() with base 10: 'undefined'
Internal Server Error: /api/update_entry/
Traceback (most recent call last):
  File "/root/venv/local/lib/python2.7/site-packages/django/core/handlers/exception.py", line 41, in inner
    response = get_response(request)
  File "/root/venv/local/lib/python2.7/site-packages/django/core/handlers/base.py", line 187, in _get_response
    response = self.process_exception_by_middleware(e, request)
  File "/root/venv/local/lib/python2.7/site-packages/django/core/handlers/base.py", line 185, in _get_response
    response = wrapped_callback(request, *callback_args, **callback_kwargs)
  File "/root/convocation-spjimr/pages/views.py", line 20, in update_entry
    stud = Student.objects.get(id=int(stud_id))
ValueError: invalid literal for int() with base 10: 'undefined'
Internal Server Error: /api/update_entry/
Traceback (most recent call last):
  File "/root/venv/local/lib/python2.7/site-packages/django/core/handlers/exception.py", line 41, in inner
    response = get_response(request)
  File "/root/venv/local/lib/python2.7/site-packages/django/core/handlers/base.py", line 187, in _get_response
    response = self.process_exception_by_middleware(e, request)
  File "/root/venv/local/lib/python2.7/site-packages/django/core/handlers/base.py", line 185, in _get_response
    response = wrapped_callback(request, *callback_args, **callback_kwargs)
  File "/root/convocation-spjimr/pages/views.py", line 20, in update_entry
    stud = Student.objects.get(id=int(stud_id))
ValueError: invalid literal for int() with base 10: 'undefined'
Internal Server Error: /api/update_entry/
Traceback (most recent call last):
  File "/root/venv/local/lib/python2.7/site-packages/django/core/handlers/exception.py", line 41, in inner
    response = get_response(request)
  File "/root/venv/local/lib/python2.7/site-packages/django/core/handlers/base.py", line 187, in _get_response
    response = self.process_exception_by_middleware(e, request)
  File "/root/venv/local/lib/python2.7/site-packages/django/core/handlers/base.py", line 185, in _get_response
    response = wrapped_callback(request, *callback_args, **callback_kwargs)
  File "/root/convocation-spjimr/pages/views.py", line 20, in update_entry
    stud = Student.objects.get(id=int(stud_id))
ValueError: invalid literal for int() with base 10: 'undefined'
Internal Server Error: /api/update_entry/
Traceback (most recent call last):
  File "/root/venv/local/lib/python2.7/site-packages/django/core/handlers/exception.py", line 41, in inner
    response = get_response(request)
  File "/root/venv/local/lib/python2.7/site-packages/django/core/handlers/base.py", line 187, in _get_response
    response = self.process_exception_by_middleware(e, request)
  File "/root/venv/local/lib/python2.7/site-packages/django/core/handlers/base.py", line 185, in _get_response
    response = wrapped_callback(request, *callback_args, **callback_kwargs)
  File "/root/convocation-spjimr/pages/views.py", line 20, in update_entry
    stud = Student.objects.get(id=int(stud_id))
ValueError: invalid literal for int() with base 10: 'undefined'
Internal Server Error: /api/update_entry/
Traceback (most recent call last):
  File "/root/venv/local/lib/python2.7/site-packages/django/core/handlers/exception.py", line 41, in inner
    response = get_response(request)
  File "/root/venv/local/lib/python2.7/site-packages/django/core/handlers/base.py", line 187, in _get_response
    response = self.process_exception_by_middleware(e, request)
  File "/root/venv/local/lib/python2.7/site-packages/django/core/handlers/base.py", line 185, in _get_response
    response = wrapped_callback(request, *callback_args, **callback_kwargs)
  File "/root/convocation-spjimr/pages/views.py", line 20, in update_entry
    stud = Student.objects.get(id=int(stud_id))
ValueError: invalid literal for int() with base 10: 'undefined'
Internal Server Error: /api/update_entry/
Traceback (most recent call last):
  File "/root/venv/local/lib/python2.7/site-packages/django/core/handlers/exception.py", line 41, in inner
    response = get_response(request)
  File "/root/venv/local/lib/python2.7/site-packages/django/core/handlers/base.py", line 187, in _get_response
    response = self.process_exception_by_middleware(e, request)
  File "/root/venv/local/lib/python2.7/site-packages/django/core/handlers/base.py", line 185, in _get_response
    response = wrapped_callback(request, *callback_args, **callback_kwargs)
  File "/root/convocation-spjimr/pages/views.py", line 20, in update_entry
    stud = Student.objects.get(id=int(stud_id))
ValueError: invalid literal for int() with base 10: 'undefined'
Internal Server Error: /api/update_entry/
Traceback (most recent call last):
  File "/root/venv/local/lib/python2.7/site-packages/django/core/handlers/exception.py", line 41, in inner
    response = get_response(request)
  File "/root/venv/local/lib/python2.7/site-packages/django/core/handlers/base.py", line 187, in _get_response
    response = self.process_exception_by_middleware(e, request)
  File "/root/venv/local/lib/python2.7/site-packages/django/core/handlers/base.py", line 185, in _get_response
    response = wrapped_callback(request, *callback_args, **callback_kwargs)
  File "/root/convocation-spjimr/pages/views.py", line 20, in update_entry
    stud = Student.objects.get(id=int(stud_id))
ValueError: invalid literal for int() with base 10: 'undefined'
Internal Server Error: /api/update_entry/
Traceback (most recent call last):
  File "/root/venv/local/lib/python2.7/site-packages/django/core/handlers/exception.py", line 41, in inner
    response = get_response(request)
  File "/root/venv/local/lib/python2.7/site-packages/django/core/handlers/base.py", line 187, in _get_response
    response = self.process_exception_by_middleware(e, request)
  File "/root/venv/local/lib/python2.7/site-packages/django/core/handlers/base.py", line 185, in _get_response
    response = wrapped_callback(request, *callback_args, **callback_kwargs)
  File "/root/convocation-spjimr/pages/views.py", line 20, in update_entry
    stud = Student.objects.get(id=int(stud_id))
ValueError: invalid literal for int() with base 10: 'undefined'
Internal Server Error: /api/update_entry/
Traceback (most recent call last):
  File "/root/venv/local/lib/python2.7/site-packages/django/core/handlers/exception.py", line 41, in inner
    response = get_response(request)
  File "/root/venv/local/lib/python2.7/site-packages/django/core/handlers/base.py", line 187, in _get_response
    response = self.process_exception_by_middleware(e, request)
  File "/root/venv/local/lib/python2.7/site-packages/django/core/handlers/base.py", line 185, in _get_response
    response = wrapped_callback(request, *callback_args, **callback_kwargs)
  File "/root/convocation-spjimr/pages/views.py", line 20, in update_entry
    stud = Student.objects.get(id=int(stud_id))
ValueError: invalid literal for int() with base 10: 'undefined'
Internal Server Error: /api/update_entry/
Traceback (most recent call last):
  File "/root/venv/local/lib/python2.7/site-packages/django/core/handlers/exception.py", line 41, in inner
    response = get_response(request)
  File "/root/venv/local/lib/python2.7/site-packages/django/core/handlers/base.py", line 187, in _get_response
    response = self.process_exception_by_middleware(e, request)
  File "/root/venv/local/lib/python2.7/site-packages/django/core/handlers/base.py", line 185, in _get_response
    response = wrapped_callback(request, *callback_args, **callback_kwargs)
  File "/root/convocation-spjimr/pages/views.py", line 20, in update_entry
    stud = Student.objects.get(id=int(stud_id))
ValueError: invalid literal for int() with base 10: 'undefined'
Internal Server Error: /api/update_entry/
Traceback (most recent call last):
  File "/root/venv/local/lib/python2.7/site-packages/django/core/handlers/exception.py", line 41, in inner
    response = get_response(request)
  File "/root/venv/local/lib/python2.7/site-packages/django/core/handlers/base.py", line 187, in _get_response
    response = self.process_exception_by_middleware(e, request)
  File "/root/venv/local/lib/python2.7/site-packages/django/core/handlers/base.py", line 185, in _get_response
    response = wrapped_callback(request, *callback_args, **callback_kwargs)
  File "/root/convocation-spjimr/pages/views.py", line 20, in update_entry
    stud = Student.objects.get(id=int(stud_id))
ValueError: invalid literal for int() with base 10: 'undefined'
Internal Server Error: /api/update_entry/
Traceback (most recent call last):
  File "/root/venv/local/lib/python2.7/site-packages/django/core/handlers/exception.py", line 41, in inner
    response = get_response(request)
  File "/root/venv/local/lib/python2.7/site-packages/django/core/handlers/base.py", line 187, in _get_response
    response = self.process_exception_by_middleware(e, request)
  File "/root/venv/local/lib/python2.7/site-packages/django/core/handlers/base.py", line 185, in _get_response
    response = wrapped_callback(request, *callback_args, **callback_kwargs)
  File "/root/convocation-spjimr/pages/views.py", line 20, in update_entry
    stud = Student.objects.get(id=int(stud_id))
ValueError: invalid literal for int() with base 10: 'undefined'
Not Found: /css/style.css
Not Found: /favicon.ico
Internal Server Error: /api/update_entry/
Traceback (most recent call last):
  File "/root/venv/local/lib/python2.7/site-packages/django/core/handlers/exception.py", line 41, in inner
    response = get_response(request)
  File "/root/venv/local/lib/python2.7/site-packages/django/core/handlers/base.py", line 187, in _get_response
    response = self.process_exception_by_middleware(e, request)
  File "/root/venv/local/lib/python2.7/site-packages/django/core/handlers/base.py", line 185, in _get_response
    response = wrapped_callback(request, *callback_args, **callback_kwargs)
  File "/root/convocation-spjimr/pages/views.py", line 20, in update_entry
    stud = Student.objects.get(id=int(stud_id))
ValueError: invalid literal for int() with base 10: 'undefined'
Not Found: /css/style.css
Internal Server Error: /api/update_entry/
Traceback (most recent call last):
  File "/root/venv/local/lib/python2.7/site-packages/django/core/handlers/exception.py", line 41, in inner
    response = get_response(request)
  File "/root/venv/local/lib/python2.7/site-packages/django/core/handlers/base.py", line 187, in _get_response
    response = self.process_exception_by_middleware(e, request)
  File "/root/venv/local/lib/python2.7/site-packages/django/core/handlers/base.py", line 185, in _get_response
    response = wrapped_callback(request, *callback_args, **callback_kwargs)
  File "/root/convocation-spjimr/pages/views.py", line 20, in update_entry
    stud = Student.objects.get(id=int(stud_id))
ValueError: invalid literal for int() with base 10: 'undefined'
Internal Server Error: /api/update_entry/
Traceback (most recent call last):
  File "/root/venv/local/lib/python2.7/site-packages/django/core/handlers/exception.py", line 41, in inner
    response = get_response(request)
  File "/root/venv/local/lib/python2.7/site-packages/django/core/handlers/base.py", line 187, in _get_response
    response = self.process_exception_by_middleware(e, request)
  File "/root/venv/local/lib/python2.7/site-packages/django/core/handlers/base.py", line 185, in _get_response
    response = wrapped_callback(request, *callback_args, **callback_kwargs)
  File "/root/convocation-spjimr/pages/views.py", line 20, in update_entry
    stud = Student.objects.get(id=int(stud_id))
ValueError: invalid literal for int() with base 10: '566p'
Not Found: /css/style.css
Internal Server Error: /api/update_entry/
Traceback (most recent call last):
  File "/root/venv/local/lib/python2.7/site-packages/django/core/handlers/exception.py", line 41, in inner
    response = get_response(request)
  File "/root/venv/local/lib/python2.7/site-packages/django/core/handlers/base.py", line 187, in _get_response
    response = self.process_exception_by_middleware(e, request)
  File "/root/venv/local/lib/python2.7/site-packages/django/core/handlers/base.py", line 185, in _get_response
    response = wrapped_callback(request, *callback_args, **callback_kwargs)
  File "/root/convocation-spjimr/pages/views.py", line 20, in update_entry
    stud = Student.objects.get(id=int(stud_id))
ValueError: invalid literal for int() with base 10: 'undefined'
Internal Server Error: /api/update_entry/
Traceback (most recent call last):
  File "/root/venv/local/lib/python2.7/site-packages/django/core/handlers/exception.py", line 41, in inner
    response = get_response(request)
  File "/root/venv/local/lib/python2.7/site-packages/django/core/handlers/base.py", line 187, in _get_response
    response = self.process_exception_by_middleware(e, request)
  File "/root/venv/local/lib/python2.7/site-packages/django/core/handlers/base.py", line 185, in _get_response
    response = wrapped_callback(request, *callback_args, **callback_kwargs)
  File "/root/convocation-spjimr/pages/views.py", line 20, in update_entry
    stud = Student.objects.get(id=int(stud_id))
ValueError: invalid literal for int() with base 10: 'undefined'
Internal Server Error: /api/update_entry/
Traceback (most recent call last):
  File "/root/venv/local/lib/python2.7/site-packages/django/core/handlers/exception.py", line 41, in inner
    response = get_response(request)
  File "/root/venv/local/lib/python2.7/site-packages/django/core/handlers/base.py", line 187, in _get_response
    response = self.process_exception_by_middleware(e, request)
  File "/root/venv/local/lib/python2.7/site-packages/django/core/handlers/base.py", line 185, in _get_response
    response = wrapped_callback(request, *callback_args, **callback_kwargs)
  File "/root/convocation-spjimr/pages/views.py", line 20, in update_entry
    stud = Student.objects.get(id=int(stud_id))
ValueError: invalid literal for int() with base 10: 'undefined'
Not Found: /user/register
